Workbook

Sheet Dashboard
A1: EXECUTIVE DASHBOARD — Vietnam Legends Festival 2026
A2: Financial Model | Local Partner: The Golf House | Event 18–23/8/2026 | KPI: tỷ VND
B4: KỊCH BẢN ĐANG CHỌN →
B5: Scenario selector ( bấm optional: Conservative / Base Case / Aggressive.) | C5: Base Case
C6: =MATCH(C5,Scenario!$D$12:$F$12,0) -> 2
B8: TỔNG NGÂN SÁCH (chi phí) | D8: TỔNG DOANH THU | F8: LỢI NHUẬN RÒNG | H8: TOUR RIGHTS ĐÃ TRẢ
B9: {=INDEX(Scenario!$D$26:$F$26,1,$C$6)/1000} -> 50 | D9: {=INDEX(Scenario!$D$15:$F$15,1,$C$6)/1000} -> 52.5 | F9: {=INDEX(Scenario!$D$31:$F$31,1,$C$6)/1000} -> 2.5 | H9: =Scenario!C7/1000 -> 2.6
B10: tỷ VND | D10: tỷ VND | F10: tỷ VND | H10: tỷ (100k USD·31/5/25)
B13: COST COVERAGE | D13: BIÊN LỢI NHUẬN | F13: ROI | H13: PEAK WORKING CAPITAL
B14: {=INDEX(Scenario!$D$33:$F$33,1,$C$6)} -> 1.05 | D14: {=INDEX(Scenario!$D$32:$F$32,1,$C$6)} -> 0.047619048 | F14: {=INDEX(Scenario!$D$34:$F$34,1,$C$6)} -> 0.05 | H14: =Cashflow!$C$3/1000 -> 2.9378525
B15: DT / chi phí | D15: % doanh thu | F15: net / chi phí | H15: tỷ VND
B18: CƠ CẤU CHI PHÍ (kịch bản chọn) — tỷ VND | F18: CƠ CẤU DOANH THU (kịch bản chọn) — tỷ VND
B19: Hạng mục | C19: Số tiền (tỷ) | D19: % tổng | F19: Nguồn thu | G19: Số tiền (tỷ) | H19: % tổng
B20: Tour Rights & Legends Fee | C20: {=INDEX(Scenario!$D$19:$F$19,1,$C$6)/1000} -> 18.85 | D20: {=INDEX(Scenario!$D$19:$F$19,1,$C$6)/INDEX(Scenario!$D$26:$F$26,1,$C$6)} -> 0.377 | F20: Title Partner | G20: {=INDEX(Scenario!$D$38:$F$38,1,$C$6)/1000} -> 18.375 | H20: {=INDEX(Scenario!$D$38:$F$38,1,$C$6)/INDEX(Scenario!$D$15:$F$15,1,$C$6)} -> 0.35
B21: Event Production | C21: {=INDEX(Scenario!$D$20:$F$20,1,$C$6)/1000} -> 10.135575 | D21: {=INDEX(Scenario!$D$20:$F$20,1,$C$6)/INDEX(Scenario!$D$26:$F$26,1,$C$6)} -> 0.2027115 | F21: Diamond Sponsor | G21: {=INDEX(Scenario!$D$39:$F$39,1,$C$6)/1000} -> 13.125 | H21: {=INDEX(Scenario!$D$39:$F$39,1,$C$6)/INDEX(Scenario!$D$15:$F$15,1,$C$6)} -> 0.25
B22: Golf Operations | C22: {=INDEX(Scenario!$D$21:$F$21,1,$C$6)/1000} -> 5.4056399 | D22: {=INDEX(Scenario!$D$21:$F$21,1,$C$6)/INDEX(Scenario!$D$26:$F$26,1,$C$6)} -> 0.1081128 | F22: Platinum Sponsor | G22: {=INDEX(Scenario!$D$40:$F$40,1,$C$6)/1000} -> 7.875 | H22: {=INDEX(Scenario!$D$40:$F$40,1,$C$6)/INDEX(Scenario!$D$15:$F$15,1,$C$6)} -> 0.15
B23: Hospitality | C23: {=INDEX(Scenario!$D$22:$F$22,1,$C$6)/1000} -> 3.3785249 | D23: {=INDEX(Scenario!$D$22:$F$22,1,$C$6)/INDEX(Scenario!$D$26:$F$26,1,$C$6)} -> 0.067570499 | F23: Official Partner | G23: {=INDEX(Scenario!$D$41:$F$41,1,$C$6)/1000} -> 5.25 | H23: {=INDEX(Scenario!$D$41:$F$41,1,$C$6)/INDEX(Scenario!$D$15:$F$15,1,$C$6)} -> 0.1
B24: Marketing & Communications | C24: {=INDEX(Scenario!$D$23:$F$23,1,$C$6)/1000} -> 6.7570499 | D24: {=INDEX(Scenario!$D$23:$F$23,1,$C$6)/INDEX(Scenario!$D$26:$F$26,1,$C$6)} -> 0.135141 | F24: VIP Packages | G24: {=INDEX(Scenario!$D$42:$F$42,1,$C$6)/1000} -> 4.2 | H24: {=INDEX(Scenario!$D$42:$F$42,1,$C$6)/INDEX(Scenario!$D$15:$F$15,1,$C$6)} -> 0.08
B25: Logistics | C25: {=INDEX(Scenario!$D$24:$F$24,1,$C$6)/1000} -> 3.4460954 | D25: {=INDEX(Scenario!$D$24:$F$24,1,$C$6)/INDEX(Scenario!$D$26:$F$26,1,$C$6)} -> 0.068921909 | F25: Pro-Am Slots | G25: {=INDEX(Scenario!$D$43:$F$43,1,$C$6)/1000} -> 2.1 | H25: {=INDEX(Scenario!$D$43:$F$43,1,$C$6)/INDEX(Scenario!$D$15:$F$15,1,$C$6)} -> 0.04
B26: Contingency | C26: {=INDEX(Scenario!$D$25:$F$25,1,$C$6)/1000} -> 2.027115 | D26: {=INDEX(Scenario!$D$25:$F$25,1,$C$6)/INDEX(Scenario!$D$26:$F$26,1,$C$6)} -> 0.040542299 | F26: Booth & Activation | G26: {=INDEX(Scenario!$D$44:$F$44,1,$C$6)/1000} -> 1.575 | H26: {=INDEX(Scenario!$D$44:$F$44,1,$C$6)/INDEX(Scenario!$D$15:$F$15,1,$C$6)} -> 0.03
B27: TỔNG NGÂN SÁCH | C27: =SUM(C20:C26) -> 50 | D27: =SUM(D20:D26) -> 1 | F27: TỔNG DOANH THU | G27: =SUM(G20:G26) -> 52.5 | H27: =SUM(H20:H26) -> 1
B28: • Tour Rights đã trả (31/5/25) | C28: =Scenario!C7/1000 -> 2.6
B30: SO SÁNH 3 KỊCH BẢN — tỷ VND
B31: Chỉ tiêu | C31: Conservative | D31: Base Case | E31: Aggressive
B32: Tổng ngân sách | C32: =Scenario!D26/1000 -> 35 | D32: =Scenario!E26/1000 -> 50 | E32: =Scenario!F26/1000 -> 70
B33: Tổng doanh thu | C33: =Scenario!D15/1000 -> 35 | D33: =Scenario!E15/1000 -> 52.5 | E33: =Scenario!F15/1000 -> 77
B34: Lợi nhuận ròng | C34: =Scenario!D31/1000 -> 0 | D34: =Scenario!E31/1000 -> 2.5 | E34: =Scenario!F31/1000 -> 7
B35: Cost coverage | C35: =Scenario!D33 -> 1 | D35: =Scenario!E33 -> 1.05 | E35: =Scenario!F33 -> 1.1
B36: ROI | C36: =Scenario!D34 -> 0 | D36: =Scenario!E34 -> 0.05 | E36: =Scenario!F34 -> 0.1
B38: Đối chiếu Reference Cost (sheet riêng): Gross 48,6 tỷ = GH net 31,8 tỷ + Đối tác/in-kind 16,8 tỷ. Phí Legends 18,85 tỷ (gồm 100k USD đã trả) cố định trong mọi kịch bản.

Sheet Reference Cost
A1: RECONCILIATION — CHI PHÍ THAM KHẢO (LT Fest 18–23/08/2026)
A2: Nguồn: file 'Chi_Phi_LT_Fest_Aug2026' (user). Section A theo USD; Section B theo VND. Quy đổi triệu VND theo USD/VND.
B4: Tỷ giá USD/VND | D4: =Scenario!C5 -> 26000
B6: A. PHÍ LEGENDS (USD)
B7: Hạng mục | C7: ĐVT | D7: SL | E7: Đơn giá (USD) | F7: Thành tiền (USD) | G7: Đối tác (USD) | H7: GolfHouse (USD) | I7: GH (triệu VND) | J7: Gross (triệu VND)
B8: Bản quyền (Tour Rights) | C8: năm | D8: 1 | E8: 100000 | F8: =D8*E8 -> 100000 | G8: 0 | H8: 100000 | I8: =H8*$D$4/1000000 -> 2600 | J8: =F8*$D$4/1000000 -> 2600 | K8: Đã thanh toán 31/05/2025
B9: Giải thưởng (Prize fund) | C9: năm | D9: 1 | E9: 1000000 | F9: =D9*E9 -> 1000000 | G9: 450000 | H9: 550000 | I9: =H9*$D$4/1000000 -> 14300 | J9: =F9*$D$4/1000000 -> 26000 | K9: Đối tác 450k + GH 550k
B10: Truyền thông quốc tế Legends | C10: năm | D10: 1 | E10: 75000 | F10: =D10*E10 -> 75000 | G10: 0 | H10: 75000 | I10: =H10*$D$4/1000000 -> 1950 | J10: =F10*$D$4/1000000 -> 1950
B11: Tổng A — Phí Legends | F11: =SUM(F8:F10) -> 1175000 | G11: =SUM(G8:G10) -> 450000 | H11: =SUM(H8:H10) -> 725000 | I11: =SUM(I8:I10) -> 18850 | J11: =SUM(J8:J10) -> 30550
B13: B. TỔ CHỨC GIẢI (VND)
B14: Hạng mục | C14: ĐVT | D14: SL | E14: Đơn giá (VND) | F14: Thành tiền (triệu) | G14: Bên chi trả | H14: GH (triệu) | I14: Partner (triệu)
B15: Vé khứ hồi nội địa (nếu có) | C15: Vé | D15: 100 | E15: 5000000 | F15: =D15*E15/1000000 -> 500 | G15: NTT | H15: =IF(G15="GH",F15,0) -> 0 | I15: =F15-H15 -> 500
B16: Họp báo | C16: Gói | D16: 1 | E16: 500000000 | F16: =D16*E16/1000000 -> 500 | G16: GH | H16: =IF(G16="GH",F16,0) -> 500 | I16: =F16-H16 -> 0
B17: Xe di chuyển – lưu trú – ăn uống 100 VĐV + 30 BTC (1 tuần) | C17: Người | D17: 130 | E17: 20000000 | F17: =D17*E17/1000000 -> 2600 | G17: NTT | H17: =IF(G17="GH",F17,0) -> 0 | I17: =F17-H17 -> 2600
B18: Sân Golf (nguyên ngày T3–CN, in-kind) | C18: Ngày | D18: 6 | E18: 0 | F18: =D18*E18/1000000 -> 0 | G18: NTT | H18: =IF(G18="GH",F18,0) -> 0 | I18: =F18-H18 -> 0
B19: Bảo hiểm giải đấu + HIO (HD Agribank) | C19: Gói | D19: 1 | E19: 1000000000 | F19: =D19*E19/1000000 -> 1000 | G19: GH | H19: =IF(G19="GH",F19,0) -> 1000 | I19: =F19-H19 -> 0
B20: Trọng tài | C20: Gói | D20: 1 | E20: 70000000 | F20: =D20*E20/1000000 -> 70 | G20: GH | H20: =IF(G20="GH",F20,0) -> 70 | I20: =F20-H20 -> 0
B21: Tổ chức sự kiện (golf / gian hàng / entertainment) | C21: Giải | D21: 1 | E21: 10000000000 | F21: =D21*E21/1000000 -> 10000 | G21: GH | H21: =IF(G21="GH",F21,0) -> 10000 | I21: =F21-H21 -> 0
B22: Truyền thông báo đài trong & ngoài nước | C22: Gói | D22: 1 | E22: 1000000000 | F22: =D22*E22/1000000 -> 1000 | G22: GH | H22: =IF(G22="GH",F22,0) -> 1000 | I22: =F22-H22 -> 0
B23: Sản xuất truyền hình trực tiếp | C23: Gói | D23: 1 | E23: 350000000 | F23: =D23*E23/1000000 -> 350 | G23: GH | H23: =IF(G23="GH",F23,0) -> 350 | I23: =F23-H23 -> 0
B24: Chi phí truyền thông Social / Digital | C24: Gói | D24: 1 | E24: 1000000000 | F24: =D24*E24/1000000 -> 1000 | G24: GH | H24: =IF(G24="GH",F24,0) -> 1000 | I24: =F24-H24 -> 0
B25: Phí dự phòng | C25: Gói | D25: 1 | E25: 1000000000 | F25: =D25*E25/1000000 -> 1000 | G25: GH | H25: =IF(G25="GH",F25,0) -> 1000 | I25: =F25-H25 -> 0
B26: Tổng B — Tổ chức giải | F26: =SUM(F15:F25) -> 18020 | H26: =SUM(H15:H25) -> 14920 | I26: =SUM(I15:I25) -> 3100
B28: TỔNG HỢP & ĐỐI CHIẾU (triệu VND)
B29: Tổng chi phí sự kiện (GROSS) | H29: =J11+F26 -> 48570
B30: Đối tác & in-kind (Partner) | H30: =G11*$D$4/1000000+I26 -> 14800
B31: Chi phí Golf House (NET CASH) | H31: =I11+H26 -> 33770
B33: CROSSWALK → hạng mục mô hình (GH net cash, tham chiếu)
B34: Hạng mục mô hình | C34: GH (triệu) | D34: % GH net
B35: Tour Rights & Legends Fee | C35: =I11 -> 18850 | D35: =C35/$C$42 -> 0.59332704
B36: Event Production | C36: =H21 -> 10000 | D36: =C36/$C$42 -> 0.31476235
B37: Golf Operations | C37: =H20 -> 70 | D37: =C37/$C$42 -> 0.0022033365
B38: Hospitality | C38: =0 -> 0 | D38: =C38/$C$42 -> 0
B39: Marketing & Communications | C39: =H16+H22+H23 -> 1850 | D39: =C39/$C$42 -> 0.058231036
B40: Logistics | C40: =0 -> 0 | D40: =C40/$C$42 -> 0
B41: Contingency | C41: =H19 -> 1000 | D41: =C41/$C$42 -> 0.031476235
B42: TỔNG (= GH net) | C42: =SUM(C35:C41) -> 31770 | D42: =SUM(D35:D41) -> 1

Sheet Event Budget
A1: EVENT BUDGET — Budget Summary
A2: Đơn vị: triệu VND | Cột SELECTED = kịch bản đang chọn. Tour Rights tách rõ phần đã trả 31/05/2025.
B3: Kịch bản: | C3: =Dashboard!C5 -> Base Case
B5: Hạng mục chi phí | C5: Tỷ trọng VH | D5: Conservative | E5: Base Case | F5: Aggressive | G5: SELECTED | H5: % tổng | I5: Ghi chú
B6: Tour Rights & Legends Fee | C6: =Scenario!C19 -> cố định | D6: =Scenario!D19 -> 18850 | E6: =Scenario!E19 -> 18850 | F6: =Scenario!F19 -> 18850 | G6: =CHOOSE(Dashboard!$C$6,D6,E6,F6) -> 18850 | H6: =G6/$G$13 -> 0.377 | I6: Phí Legends cố định (link Reference)
B7: Event Production | C7: =Scenario!C20 -> 0.15 | D7: =Scenario!D20 -> 5254.8807 | E7: =Scenario!E20 -> 10135.575 | F7: =Scenario!F20 -> 16643.167 | G7: =CHOOSE(Dashboard!$C$6,D7,E7,F7) -> 10135.575 | H7: =G7/$G$13 -> 0.2027115 | I7: Tổ chức sự kiện
B8: Golf Operations | C8: =Scenario!C21 -> 0.08 | D8: =Scenario!D21 -> 2802.603 | E8: =Scenario!E21 -> 5405.6399 | F8: =Scenario!F21 -> 8876.3557 | G8: =CHOOSE(Dashboard!$C$6,D8,E8,F8) -> 5405.6399 | H8: =G8/$G$13 -> 0.1081128 | I8: Trọng tài
B9: Hospitality | C9: =Scenario!C22 -> 0.05 | D9: =Scenario!D22 -> 1751.6269 | E9: =Scenario!E22 -> 3378.5249 | F9: =Scenario!F22 -> 5547.7223 | G9: =CHOOSE(Dashboard!$C$6,D9,E9,F9) -> 3378.5249 | H9: =G9/$G$13 -> 0.067570499 | I9: (gồm trong tổ chức SK)
B10: Marketing & Communications | C10: =Scenario!C23 -> 0.1 | D10: =Scenario!D23 -> 3503.2538 | E10: =Scenario!E23 -> 6757.0499 | F10: =Scenario!F23 -> 11095.445 | G10: =CHOOSE(Dashboard!$C$6,D10,E10,F10) -> 6757.0499 | H10: =G10/$G$13 -> 0.135141 | I10: Họp báo+báo đài+SX TH
B11: Logistics | C11: =Scenario!C24 -> 0.051 | D11: =Scenario!D24 -> 1786.6594 | E11: =Scenario!E24 -> 3446.0954 | F11: =Scenario!F24 -> 5658.6768 | G11: =CHOOSE(Dashboard!$C$6,D11,E11,F11) -> 3446.0954 | H11: =G11/$G$13 -> 0.068921909 | I11: Vé+vận chuyển
B12: Contingency | C12: =Scenario!C25 -> 0.03 | D12: =Scenario!D25 -> 1050.9761 | E12: =Scenario!E25 -> 2027.115 | F12: =Scenario!F25 -> 3328.6334 | G12: =CHOOSE(Dashboard!$C$6,D12,E12,F12) -> 2027.115 | H12: =G12/$G$13 -> 0.040542299 | I12: Bảo hiểm+HIO
B13: TỔNG NGÂN SÁCH | D13: =SUM(D6:D12) -> 35000 | E13: =SUM(E6:E12) -> 50000 | F13: =SUM(F6:F12) -> 70000 | G13: =SUM(G6:G12) -> 50000 | H13: =SUM(H6:H12) -> 1
B15: CHI TIẾT TOUR RIGHTS & LEGENDS FEE (USD)
B16: Bản quyền (Tour Rights) — đã trả 31/05/2025 | E16: =Scenario!C6 -> 100000 | G16: =Scenario!C7 -> 2600
B17: Giải thưởng (Prize) — phần GH | E17: ='Reference Cost'!H9 -> 550000 | G17: ='Reference Cost'!I9 -> 14300
B18: Truyền thông quốc tế Legends | E18: ='Reference Cost'!H10 -> 75000 | G18: ='Reference Cost'!I10 -> 1950
B19: Tổng Legends fee (cố định) | G19: =Scenario!C9 -> 18850
B21: Manpower + Vendor (bottom-up, gross): | G21: =Manpower!E2+Vendor!G2 -> 33462

Sheet Budget Detail
A1: DETAILED BUDGET BREAKDOWN (SELECTED scenario)
A2: Đơn vị: triệu VND | Số tiền dòng = tổng hạng mục (SELECTED) × tỷ trọng nội bộ (input xanh).
B4: Hạng mục / dòng chi tiết | C4: Tỷ trọng nội bộ | D4: Số tiền (triệu) | E4: Ghi chú
B5: Tour Rights & Legends Fee | D5: ='Event Budget'!G6 -> 18850 | E5: Tổng hạng mục
B6: Bản quyền (đã trả 100k USD · 31/5/25) | C6: 0.138 | D6: =$D$5*C6 -> 2601.3 | E6: Sunk cost
B7: Giải thưởng – phần GH (550k USD) | C7: 0.759 | D7: =$D$5*C7 -> 14307.15 | E7: Prize fund
B8: Truyền thông quốc tế Legends (75k USD) | C8: 0.103 | D8: =$D$5*C8 -> 1941.55
B9: Check (Σ−tổng) | C9: =SUM(C6:C8) -> 1 | D9: =SUM(D6:D8)-D5 -> 0
B11: Event Production | D11: ='Event Budget'!G7 -> 10135.575 | E11: Tổng hạng mục
B12: Overlay & temporary structures | C12: 0.34 | D12: =$D$11*C12 -> 3446.0954
B13: Technical (AV, LED, power) | C13: 0.3 | D13: =$D$11*C13 -> 3040.6725
B14: Branding & signage | C14: 0.16 | D14: =$D$11*C14 -> 1621.692
B15: Gian hàng & entertainment | C15: 0.2 | D15: =$D$11*C15 -> 2027.115
B16: Check (Σ−tổng) | C16: =SUM(C12:C15) -> 1 | D16: =SUM(D12:D15)-D11 -> 0
B18: Golf Operations | D18: ='Event Budget'!G8 -> 5405.6399 | E18: Tổng hạng mục
B19: Course setup & agronomy | C19: 0.45 | D19: =$D$18*C19 -> 2432.538
B20: Scoring & leaderboard | C20: 0.25 | D20: =$D$18*C20 -> 1351.41
B21: Caddies, carts & on-course | C21: 0.3 | D21: =$D$18*C21 -> 1621.692
B22: Check (Σ−tổng) | C22: =SUM(C19:C21) -> 1 | D22: =SUM(D19:D21)-D18 -> 0
B24: Hospitality | D24: ='Event Budget'!G9 -> 3378.5249 | E24: Tổng hạng mục
B25: VIP lounge & F&B | C25: 0.45 | D25: =$D$24*C25 -> 1520.3362
B26: Welcome dinner | C26: 0.2 | D26: =$D$24*C26 -> 675.70499
B27: Gala & awards | C27: 0.35 | D27: =$D$24*C27 -> 1182.4837
B28: Check (Σ−tổng) | C28: =SUM(C25:C27) -> 1 | D28: =SUM(D25:D27)-D24 -> 0
B30: Marketing & Communications | D30: ='Event Budget'!G10 -> 6757.0499 | E30: Tổng hạng mục
B31: Broadcast & livestream | C31: 0.3 | D31: =$D$30*C31 -> 2027.115
B32: Content & creative | C32: 0.2 | D32: =$D$30*C32 -> 1351.41
B33: PR, media & social | C33: 0.25 | D33: =$D$30*C33 -> 1689.2625
B34: OOH / media buying | C34: 0.25 | D34: =$D$30*C34 -> 1689.2625
B35: Check (Σ−tổng) | C35: =SUM(C31:C34) -> 1 | D35: =SUM(D31:D34)-D30 -> 0
B37: Logistics | D37: ='Event Budget'!G11 -> 3446.0954 | E37: Tổng hạng mục
B38: Accommodation (room block) | C38: 0.4 | D38: =$D$37*C38 -> 1378.4382
B39: Transport & fleet | C39: 0.35 | D39: =$D$37*C39 -> 1206.1334
B40: Cargo & customs | C40: 0.25 | D40: =$D$37*C40 -> 861.52386
B41: Check (Σ−tổng) | C41: =SUM(C38:C40) -> 1 | D41: =SUM(D38:D40)-D37 -> 0
B43: Contingency | D43: ='Event Budget'!G12 -> 2027.115 | E43: Tổng hạng mục
B44: Bảo hiểm + HIO & dự phòng vận hành | C44: 0.7 | D44: =$D$43*C44 -> 1418.9805
B45: FX & price escalation buffer | C45: 0.3 | D45: =$D$43*C45 -> 608.13449
B46: Check (Σ−tổng) | C46: =SUM(C44:C45) -> 1 | D46: =SUM(D44:D45)-D43 -> 0

Sheet Manpower
A1: MANPOWER COSTING
D2: TỔNG CHI PHÍ NHÂN SỰ (triệu): | E2: =G23 -> 2262
A3: Đơn vị: triệu VND | Cost = Headcount × Số tháng × Đơn giá/tháng.
B4: Vị trí / chức năng | C4: Khối | D4: Headcount | E4: Số tháng | F4: Đơn giá/tháng | G4: Chi phí
B5: Festival Director | C5: Admin | D5: 1 | E5: 3 | F5: 60 | G5: =D5*E5*F5 -> 180
B6: Operations Director | C6: Admin | D6: 1 | E6: 3 | F6: 45 | G6: =D6*E6*F6 -> 135
B7: Commercial Director | C7: Admin | D7: 1 | E7: 3 | F7: 45 | G7: =D7*E7*F7 -> 135
B8: PMO / Coordinators | C8: Admin | D8: 2 | E8: 3 | F8: 20 | G8: =D8*E8*F8 -> 120
B9: Finance & Procurement | C9: Admin | D9: 1 | E9: 3 | F9: 25 | G9: =D9*E9*F9 -> 75
B10: Legal & Compliance | C10: Admin | D10: 1 | E10: 3 | F10: 25 | G10: =D10*E10*F10 -> 75
B11: Government & Protocol | C11: Admin | D11: 1 | E11: 3 | F11: 22 | G11: =D11*E11*F11 -> 66
B12: Tournament Ops team | C12: Golf | D12: 3 | E12: 3 | F12: 22 | G12: =D12*E12*F12 -> 198
B13: Player Services team | C13: Golf | D13: 4 | E13: 1 | F13: 15 | G13: =D13*E13*F13 -> 60
B14: Hospitality & VIP team | C14: Hospitality | D14: 4 | E14: 1 | F14: 18 | G14: =D14*E14*F14 -> 72
B15: Media, PR & Content | C15: Marketing | D15: 5 | E15: 3 | F15: 16 | G15: =D15*E15*F15 -> 240
B16: Broadcast liaison & crew | C16: Marketing | D16: 6 | E16: 2 | F16: 18 | G16: =D16*E16*F16 -> 216
... B22: Interpreters & liaison | C22: Hospitality | D22: 6 | E22: 1 | F22: 15 | G22: =D22*E22*F22 -> 90
B23: TỔNG NHÂN SỰ | D23: =SUM(D5:D22) -> 203 | G23: =SUM(G5:G22) -> 2262
B25: % của ngân sách Base Case | G25: =G23/Scenario!E26 -> 0.04524

Sheet Vendor
A1: VENDOR COSTING
F2: TỔNG CHI PHÍ VENDOR (triệu): | G2: =G25 -> 31200
A3: Đơn vị: triệu VND | Cost = Qty × Đơn giá. Deposit% = tạm ứng khi ký.
B4: Gói vendor | C4: Khối | D4: ĐVT | E4: Qty | F4: Đơn giá | G4: Chi phí | H4: Deposit %
B5: Overlay & structures | C5: Production | D5: gói | E5: 1 | F5: 2600 | G5: =E5*F5 -> 2600 | H5: 0.4
B6: AV, LED & technical | C6: Production | D6: gói | E6: 1 | F6: 2400 | G6: =E6*F6 -> 2400 | H6: 0.4
B7: Stage, gala & ceremony | C7: Production | D7: gói | E7: 1 | F7: 1500 | G7: =E7*F7 -> 1500 | H7: 0.3
B8: Branding & signage | C8: Production | D8: gói | E8: 1 | F8: 1100 | G8: =E8*F8 -> 1100 | H8: 0.3
B9: Course setup & agronomy | C9: Golf | D9: gói | E9: 1 | F9: 1500 | G9: =E9*F9 -> 1500 | H9: 0.3
B10: Scoring & leaderboard | C10: Golf | D10: gói | E10: 1 | F10: 1300 | G10: =E10*F10 -> 1300 | H10: 0.5
B11: Caddies, carts & on-course | C11: Golf | D11: gói | E11: 1 | F11: 1500 | G11: =E11*F11 -> 1500 | H11: 0.3
B12: Broadcast & livestream | C12: Marketing | D12: gói | E12: 1 | F12: 3200 | G12: =E12*F12 -> 3200 | H12: 0.4
B13: Content & photography | C13: Marketing | D13: gói | E13: 1 | F13: 1200 | G13: =E13*F13 -> 1200 | H13: 0.3
B14: OOH / media buying | C14: Marketing | D14: gói | E14: 1 | F14: 2000 | G14: =E14*F14 -> 2000 | H14: 0.5
B15: Hospitality build & F&B | C15: Hospitality | D15: gói | E15: 1 | F15: 2600 | G15: =E15*F15 -> 2600 | H15: 0.3
B16: Welcome dinner & gala | C16: Hospitality | D16: gói | E16: 1 | F16: 1700 | G16: =E16*F16 -> 1700 | H16: 0.3
... B24: Event & liability insurance | C24: Contingency | D24: gói | E24: 1 | F24: 900 | G24: =E24*F24 -> 900 | H24: 1
B25: TỔNG VENDOR | G25: =SUM(G5:G24) -> 31200
B27: % của ngân sách Base Case | G27: =G25/Scenario!E26 -> 0.624
B28: Tạm ứng khi ký (deposit): | G28: =SUMPRODUCT(G5:G24,H5:H24) -> 11640

Sheet Sponsorship
A1: SPONSORSHIP REVENUE MODEL
A2: Đơn vị: triệu VND | Target theo kịch bản; Pipeline ≥ 3×.
B4: Hạng tài trợ | C4: Giá gói (range) | D4: Số slot | E4: Conservative | F4: Base Case | G4: Aggressive | H4: SELECTED | I4: Commit % | J4: Pipeline (3×)
B5: Title Partner | C5: 15–25 tỷ | D5: 1 | E5: =Scenario!D38 -> 12250 | F5: =Scenario!E38 -> 18375 | G5: =Scenario!F38 -> 26950 | H5: =CHOOSE(Dashboard!$C$6,E5,F5,G5) -> 18375 | I5: 0.7 | J5: =H5*3 -> 55125
B6: Diamond Sponsor | C6: 10–15 tỷ | D6: 2 | E6: =Scenario!D39 -> 8750 | F6: =Scenario!E39 -> 13125 | G6: =Scenario!F39 -> 19250 | H6: =CHOOSE(Dashboard!$C$6,E6,F6,G6) -> 13125 | I6: 0.6 | J6: =H6*3 -> 39375
B7: Platinum Sponsor | C7: 6–10 tỷ | D7: 3 | E7: =Scenario!D40 -> 5250 | F7: =Scenario!E40 -> 7875 | G7: =Scenario!F40 -> 11550 | H7: =CHOOSE(Dashboard!$C$6,E7,F7,G7) -> 7875 | I7: 0.5 | J7: =H7*3 -> 23625
B8: Official Partner | C8: 3–6 tỷ | D8: 4 | E8: =Scenario!D41 -> 3500 | F8: =Scenario!E41 -> 5250 | G8: =Scenario!F41 -> 7700 | H8: =CHOOSE(Dashboard!$C$6,E8,F8,G8) -> 5250 | I8: 0.45 | J8: =H8*3 -> 15750
B9: TỔNG TÀI TRỢ | E9: =SUM(E5:E8) -> 29750 | F9: =SUM(F5:F8) -> 44625 | G9: =SUM(G5:G8) -> 65450 | H9: =SUM(H5:H8) -> 44625 | J9: =SUM(J5:J8) -> 133875
B11: Pipeline weighted (risk-adjusted): | H11: =SUMPRODUCT(H5:H8,I5:I8) -> 27037.5

Sheet Commercial
A1: COMMERCIAL REVENUE MODEL
A2: Đơn vị: triệu VND | Implied units = Target / Đơn giá.
B4: Nguồn thu | C4: Đơn giá/unit | D4: Conservative | E4: Base Case | F4: Aggressive | G4: SELECTED | H4: Implied units
B5: VIP Packages | C5: 250 | D5: =Scenario!D42 -> 2800 | E5: =Scenario!E42 -> 4200 | F5: =Scenario!F42 -> 6160 | G5: =CHOOSE(Dashboard!$C$6,D5,E5,F5) -> 4200 | H5: =ROUND(G5/C5,0) -> 17
B6: Pro-Am Slots | C6: 400 | D6: =Scenario!D43 -> 1400 | E6: =Scenario!E43 -> 2100 | F6: =Scenario!F43 -> 3080 | G6: =CHOOSE(Dashboard!$C$6,D6,E6,F6) -> 2100 | H6: =ROUND(G6/C6,0) -> 5
B7: Booth & Activation | C7: 350 | D7: =Scenario!D44 -> 1050 | E7: =Scenario!E44 -> 1575 | F7: =Scenario!F44 -> 2310 | G7: =CHOOSE(Dashboard!$C$6,D7,E7,F7) -> 1575 | H7: =ROUND(G7/C7,0) -> 5
B8: TỔNG THƯƠNG MẠI | D8: =SUM(D5:D7) -> 5250 | E8: =SUM(E5:E7) -> 7875 | F8: =SUM(F5:F7) -> 11550 | G8: =SUM(G5:G7) -> 7875

Sheet Cashflow
A1: MONTHLY CASHFLOW — 06/2025 → Event (18–23/8/2026) → Post-Event
A2: Đơn vị: triệu VND | Opening = Tour Rights 100k USD đã trả 31/05/2025. Funding draw giữ tồn quỹ ≥ 0.
B3: PEAK WORKING CAPITAL (triệu): | C3: =MAX(C37:U37) -> 2937.8525
B5: Tháng (relative) | C5: Opening ≤31/05/25 | D5: T-14 | E5: T-13 | F5: T-12 | G5: T-11 | H5: T-10 | I5: T-9 | J5: T-8 | K5: T-7 | L5: T-6 | M5: T-5 | N5: T-4 | O5: T-3 | P5: T-2 | Q5: T-1 | R5: T0 | S5: T+1 | T5: T+2 | U5: T+3 | V5: TỔNG
B6: Lịch (MM/YY) | C6: 05/25 | D6: 06/25 | E6: 07/25 | F6: 08/25 | G6: 09/25 | H6: 10/25 | I6: 11/25 | J6: 12/25 | K6: 01/26 | L6: 02/26 | M6: 03/26 | N6: 04/26 | O6: 05/26 | P6: 06/26 | Q6: 07/26 | R6: 08/26 | S6: 09/26 | T6: 10/26 | U6: 11/26
B8: PHASING ASSUMPTIONS (% theo dòng — input xanh) | V8: Σ
B9: Tour Rights & Legends Fee | C9: đã trả | D9: 0 | E9: 0 | F9: 0 | G9: 0 | H9: 0 | I9: 0.06 | J9: 0 | K9: 0 | L9: 0 | M9: 0 | N9: 0 | O9: 0.06 | P9: 0 | Q9: 0.88 | R9: 0 | S9: 0 | T9: 0 | U9: 0 | V9: =SUM(D9:U9) -> 1
B10: Event Production | C10: 0 | D10: 0 | E10: 0 | F10: 0 | G10: 0 | H10: 0 | I10: 0 | J10: 0 | K10: 0 | L10: 0 | M10: 0.05 | N10: 0.1 | O10: 0.15 | P10: 0.2 | Q10: 0.25 | R10: 0.25 | S10: 0 | T10: 0 | U10: 0 | V10: =SUM(D10:U10) -> 1
B11: Golf Operations | C11: 0 | D11: 0 | E11: 0 | F11: 0 | G11: 0 | H11: 0 | I11: 0 | J11: 0 | K11: 0 | L11: 0 | M11: 0 | N11: 0 | O11: 0.1 | P11: 0.2 | Q11: 0.3 | R11: 0.4 | S11: 0 | T11: 0 | U11: 0 | V11: =SUM(D11:U11) -> 1
B12: Hospitality | C12: 0 | D12: 0 | E12: 0 | F12: 0 | G12: 0 | H12: 0 | I12: 0 | J12: 0 | K12: 0 | L12: 0 | M12: 0 | N12: 0 | O12: 0.08 | P12: 0.17 | Q12: 0.3 | R12: 0.45 | S12: 0 | T12: 0 | U12: 0 | V12: =SUM(D12:U12) -> 1
B13: Marketing & Communications | C13: 0 | D13: 0 | E13: 0 | F13: 0 | G13: 0 | H13: 0.05 | I13: 0 | J13: 0.1 | K13: 0 | L13: 0.1 | M13: 0 | N13: 0.15 | O13: 0.15 | P13: 0.15 | Q13: 0.15 | R13: 0.15 | S13: 0 | T13: 0 | U13: 0 | V13: =SUM(D13:U13) -> 1
B14: Logistics | C14: 0 | D14: 0 | E14: 0 | F14: 0 | G14: 0 | H14: 0 | I14: 0 | J14: 0 | K14: 0 | L14: 0 | M14: 0 | N14: 0 | O14: 0 | P14: 0.3 | Q14: 0.35 | R14: 0.35 | S14: 0 | T14: 0 | U14: 0 | V14: =SUM(D14:U14) -> 1
B15: Contingency | C15: 0 | D15: 0 | E15: 0 | F15: 0 | G15: 0 | H15: 0 | I15: 0 | J15: 0 | K15: 0 | L15: 0 | M15: 0 | N15: 0.2 | O15: 0 | P15: 0 | Q15: 0.3 | R15: 0.5 | S15: 0 | T15: 0 | U15: 0 | V15: =SUM(D15:U15) -> 1
B16: Sponsorship | C16: 0 | D16: 0 | E16: 0 | F16: 0 | G16: 0 | H16: 0 | I16: 0.06 | J16: 0.08 | K16: 0.08 | L16: 0.1 | M16: 0.1 | N16: 0.1 | O16: 0.1 | P16: 0.1 | Q16: 0.1 | R16: 0.1 | S16: 0.08 | T16: 0 | U16: 0 | V16: =SUM(D16:U16) -> 1
B17: Commercial | C17: 0 | D17: 0 | E17: 0 | F17: 0 | G17: 0 | H17: 0 | I17: 0 | J17: 0 | K17: 0 | L17: 0 | M17: 0 | N17: 0 | O17: 0.1 | P17: 0.15 | Q17: 0.2 | R17: 0.35 | S17: 0.2 | T17: 0 | U17: 0 | V17: =SUM(D17:U17) -> 1
B19: DÒNG TIỀN (triệu VND) | V19: Tổng
B20: DÒNG TIỀN VÀO
B21: Tài trợ (Sponsorship) | C21: 0 | D21: {=INDEX(Scenario!$D$46:$F$46,1,Dashboard!$C$6)*D16} -> 0 | E21: {=INDEX(Scenario!$D$46:$F$46,1,Dashboard!$C$6)*E16} -> 0 | F21: {=INDEX(Scenario!$D$46:$F$46,1,Dashboard!$C$6)*F16} -> 0 | G21: {=INDEX(Scenario!$D$46:$F$46,1,Dashboard!$C$6)*G16} -> 0 | H21: {=INDEX(Scenario!$D$46:$F$46,1,Dashboard!$C$6)*H16} -> 0 | I21: {=INDEX(Scenario!$D$46:$F$46,1,Dashboard!$C$6)*I16} -> 2677.5 | J21: {=INDEX(Scenario!$D$46:$F$46,1,Dashboard!$C$6)*J16} -> 3570 | K21: {=INDEX(Scenario!$D$46:$F$46,1,Dashboard!$C$6)*K16} -> 3570 | ... U21: {=INDEX(Scenario!$D$46:$F$46,1,Dashboard!$C$6)*U16} -> 0 | V21: =SUM(C21:U21) -> 44625
B22: Thương mại (Commercial) | C22: 0 | D22: {=INDEX(Scenario!$D$47:$F$47,1,Dashboard!$C$6)*D17} -> 0 | E22: {=INDEX(Scenario!$D$47:$F$47,1,Dashboard!$C$6)*E17} -> 0 | F22: {=INDEX(Scenario!$D$47:$F$47,1,Dashboard!$C$6)*F17} -> 0 | G22: {=INDEX(Scenario!$D$47:$F$47,1,Dashboard!$C$6)*G17} -> 0 | H22: {=INDEX(Scenario!$D$47:$F$47,1,Dashboard!$C$6)*H17} -> 0 | I22: {=INDEX(Scenario!$D$47:$F$47,1,Dashboard!$C$6)*I17} -> 0 | J22: {=INDEX(Scenario!$D$47:$F$47,1,Dashboard!$C$6)*J17} -> 0 | K22: {=INDEX(Scenario!$D$47:$F$47,1,Dashboard!$C$6)*K17} -> 0 | ... U22: {=INDEX(Scenario!$D$47:$F$47,1,Dashboard!$C$6)*U17} -> 0 | V22: =SUM(C22:U22) -> 7875
B23: Tổng tiền vào | C23: =SUM(C21:C22) -> 0 | D23: =SUM(D21:D22) -> 0 | E23: =SUM(E21:E22) -> 0 | F23: =SUM(F21:F22) -> 0 | G23: =SUM(G21:G22) -> 0 | H23: =SUM(H21:H22) -> 0 | I23: =SUM(I21:I22) -> 2677.5 | J23: =SUM(J21:J22) -> 3570 | ... U23: =SUM(U21:U22) -> 0 | V23: =SUM(C23:U23) -> 52500
B25: DÒNG TIỀN RA
B26: Tour Rights & Legends Fee | C26: =Scenario!$C$7 -> 2600 | D26: =(('Event Budget'!$G$6)-Scenario!$C$7)*D9 -> 0 | E26: =(('Event Budget'!$G$6)-Scenario!$C$7)*E9 -> 0 | F26: =(('Event Budget'!$G$6)-Scenario!$C$7)*F9 -> 0 | G26: =(('Event Budget'!$G$6)-Scenario!$C$7)*G9 -> 0 | H26: =(('Event Budget'!$G$6)-Scenario!$C$7)*H9 -> 0 | I26: =(('Event Budget'!$G$6)-Scenario!$C$7)*I9 -> 975 | J26: =(('Event Budget'!$G$6)-Scenario!$C$7)*J9 -> 0 | K26: =(('Event Budget'!$G$6)-Scenario!$C$7)*K9 -> 0 | ... U26: =(('Event Budget'!$G$6)-Scenario!$C$7)*U9 -> 0 | V26: =SUM(C26:U26) -> 18850
B27: Event Production | C27: 0 | D27: ='Event Budget'!$G$7*D10 -> 0 | E27: ='Event Budget'!$G$7*E10 -> 0 | F27: ='Event Budget'!$G$7*F10 -> 0 | G27: ='Event Budget'!$G$7*G10 -> 0 | H27: ='Event Budget'!$G$7*H10 -> 0 | I27: ='Event Budget'!$G$7*I10 -> 0 | J27: ='Event Budget'!$G$7*J10 -> 0 | K27: ='Event Budget'!$G$7*K10 -> 0 | ... U27: ='Event Budget'!$G$7*U10 -> 0 | V27: =SUM(C27:U27) -> 10135.575
B28: Golf Operations | C28: 0 | D28: ='Event Budget'!$G$8*D11 -> 0 | E28: ='Event Budget'!$G$8*E11 -> 0 | F28: ='Event Budget'!$G$8*F11 -> 0 | G28: ='Event Budget'!$G$8*G11 -> 0 | H28: ='Event Budget'!$G$8*H11 -> 0 | I28: ='Event Budget'!$G$8*I11 -> 0 | J28: ='Event Budget'!$G$8*J11 -> 0 | K28: ='Event Budget'!$G$8*K11 -> 0 | ... U28: ='Event Budget'!$G$8*U11 -> 0 | V28: =SUM(C28:U28) -> 5405.6399
B29: Hospitality | C29: 0 | D29: ='Event Budget'!$G$9*D12 -> 0 | E29: ='Event Budget'!$G$9*E12 -> 0 | F29: ='Event Budget'!$G$9*F12 -> 0 | G29: ='Event Budget'!$G$9*G12 -> 0 | H29: ='Event Budget'!$G$9*H12 -> 0 | I29: ='Event Budget'!$G$9*I12 -> 0 | J29: ='Event Budget'!$G$9*J12 -> 0 | K29: ='Event Budget'!$G$9*K12 -> 0 | ... U29: ='Event Budget'!$G$9*U12 -> 0 | V29: =SUM(C29:U29) -> 3378.5249
B30: Marketing & Communications | C30: 0 | D30: ='Event Budget'!$G$10*D13 -> 0 | E30: ='Event Budget'!$G$10*E13 -> 0 | F30: ='Event Budget'!$G$10*F13 -> 0 | G30: ='Event Budget'!$G$10*G13 -> 0 | H30: ='Event Budget'!$G$10*H13 -> 337.85249 | I30: ='Event Budget'!$G$10*I13 -> 0 | J30: ='Event Budget'!$G$10*J13 -> 675.70499 | K30: ='Event Budget'!$G$10*K13 -> 0 | ... U30: ='Event Budget'!$G$10*U13 -> 0 | V30: =SUM(C30:U30) -> 6757.0499
B31: Logistics | C31: 0 | D31: ='Event Budget'!$G$11*D14 -> 0 | E31: ='Event Budget'!$G$11*E14 -> 0 | F31: ='Event Budget'!$G$11*F14 -> 0 | G31: ='Event Budget'!$G$11*G14 -> 0 | H31: ='Event Budget'!$G$11*H14 -> 0 | I31: ='Event Budget'!$G$11*I14 -> 0 | J31: ='Event Budget'!$G$11*J14 -> 0 | K31: ='Event Budget'!$G$11*K14 -> 0 | ... U31: ='Event Budget'!$G$11*U14 -> 0 | V31: =SUM(C31:U31) -> 3446.0954
B32: Contingency | C32: 0 | D32: ='Event Budget'!$G$12*D15 -> 0 | E32: ='Event Budget'!$G$12*E15 -> 0 | F32: ='Event Budget'!$G$12*F15 -> 0 | G32: ='Event Budget'!$G$12*G15 -> 0 | H32: ='Event Budget'!$G$12*H15 -> 0 | I32: ='Event Budget'!$G$12*I15 -> 0 | J32: ='Event Budget'!$G$12*J15 -> 0 | K32: ='Event Budget'!$G$12*K15 -> 0 | ... U32: ='Event Budget'!$G$12*U15 -> 0 | V32: =SUM(C32:U32) -> 2027.115
B33: Tổng tiền ra | C33: =SUM(C26:C32) -> 2600 | D33: =SUM(D26:D32) -> 0 | E33: =SUM(E26:E32) -> 0 | F33: =SUM(F26:F32) -> 0 | G33: =SUM(G26:G32) -> 0 | H33: =SUM(H26:H32) -> 337.85249 | I33: =SUM(I26:I32) -> 975 | J33: =SUM(J26:J32) -> 675.70499 | ... U33: =SUM(U26:U32) -> 0 | V33: =SUM(C33:U33) -> 50000
B35: Dòng tiền hoạt động ròng | C35: =C23-C33 -> -2600 | D35: =D23-D33 -> 0 | E35: =E23-E33 -> 0 | F35: =F23-F33 -> 0 | G35: =G23-G33 -> 0 | H35: =H23-H33 -> -337.85249 | I35: =I23-I33 -> 1702.5 | J35: =J23-J33 -> 2894.295 | ... U35: =U23-U33 -> 0 | V35: =SUM(C35:U35) -> 2500
B36: Luỹ kế hoạt động (trước funding) | C36: =C35 -> -2600 | D36: =C36+D35 -> -2600 | E36: =D36+E35 -> -2600 | F36: =E36+F35 -> -2600 | G36: =F36+G35 -> -2600 | H36: =G36+H35 -> -2937.8525 | I36: =H36+I35 -> -1235.3525 | J36: =I36+J35 -> 1658.9425 | K36: =J36+K35 -> 5228.9425 | ... U36: =T36+U35 -> 2500
B37: Funding luỹ kế cần (đệm 0) | C37: =MAX(0,-C36) -> 2600 | D37: =MAX(0,-D36) -> 2600 | E37: =MAX(0,-E36) -> 2600 | F37: =MAX(0,-F36) -> 2600 | G37: =MAX(0,-G36) -> 2600 | H37: =MAX(0,-H36) -> 2937.8525 | I37: =MAX(0,-I36) -> 1235.3525 | J37: =MAX(0,-J36) -> 0 | ... U37: =MAX(0,-U36) -> 0
B38: Funding draw trong kỳ | C38: =C37 -> 2600 | D38: =MAX(0,D37-C37) -> 0 | E38: =MAX(0,E37-D37) -> 0 | F38: =MAX(0,F37-E37) -> 0 | G38: =MAX(0,G37-F37) -> 0 | H38: =MAX(0,H37-G37) -> 337.85249 | I38: =MAX(0,I37-H37) -> 0 | J38: =MAX(0,J37-I37) -> 0 | K38: =MAX(0,K37-J37) -> 0 | ... U38: =MAX(0,U37-T37) -> 0
B39: Tồn quỹ cuối kỳ (sau funding) | C39: =C36+C37 -> 0 | D39: =D36+D37 -> 0 | E39: =E36+E37 -> 0 | F39: =F36+F37 -> 0 | G39: =G36+G37 -> 0 | H39: =H36+H37 -> 0 | I39: =I36+I37 -> 0 | J39: =J36+J37 -> 1658.9425 | ... U39: =U36+U37 -> 2500

Sheet Scenario
A1: SCENARIO ANALYSIS — Conservative / Base / Aggressive
A2: Đơn vị: triệu VND | Tổng chi phí = quy mô; Phí Legends cố định (link Reference); vận hành lấp phần còn lại. Input xanh.
B4: GIẢ ĐỊNH CHUNG
B5: Tỷ giá USD/VND | C5: 26000
B6: Tour Rights đã thanh toán (USD) | C6: 100000
B7: Tour Rights đã thanh toán (triệu VND) | C7: =C5*C6/1000000 -> 2600
B8: Ngày thanh toán | C8: 31/05/2025
B9: Phí Legends cố định (bản quyền + giải thưởng + TT quốc tế) | C9: ='Reference Cost'!$I$11 -> 18850
B11: KỊCH BẢN
B12: Chỉ tiêu | C12: Tỷ trọng | D12: Conservative | E12: Base Case | F12: Aggressive
B13: Tổng chi phí (Total Budget) | D13: 35000 | E13: 50000 | F13: 70000
B14: Hệ số phủ chi phí (revenue coverage) | D14: 1 | E14: 1.05 | F14: 1.1
B15: Tổng doanh thu mục tiêu | D15: =D13*D14 -> 35000 | E15: =E13*E14 -> 52500 | F15: =F13*F14 -> 77000
B17: CHI PHÍ THEO HẠNG MỤC
B18: Hạng mục | C18: Tỷ trọng VH | D18: Conservative | E18: Base Case | F18: Aggressive
B19: Tour Rights & Legends Fee | C19: cố định | D19: =$C$9 -> 18850 | E19: =$C$9 -> 18850 | F19: =$C$9 -> 18850
B20: Event Production | C20: 0.15 | D20: =(D$13-$C$9)*C20/SUM($C$20:$C$25) -> 5254.8807 | E20: =(E$13-$C$9)*C20/SUM($C$20:$C$25) -> 10135.575 | F20: =(F$13-$C$9)*C20/SUM($C$20:$C$25) -> 16643.167
B21: Golf Operations | C21: 0.08 | D21: =(D$13-$C$9)*C21/SUM($C$20:$C$25) -> 2802.603 | E21: =(E$13-$C$9)*C21/SUM($C$20:$C$25) -> 5405.6399 | F21: =(F$13-$C$9)*C21/SUM($C$20:$C$25) -> 8876.3557
B22: Hospitality | C22: 0.05 | D22: =(D$13-$C$9)*C22/SUM($C$20:$C$25) -> 1751.6269 | E22: =(E$13-$C$9)*C22/SUM($C$20:$C$25) -> 3378.5249 | F22: =(F$13-$C$9)*C22/SUM($C$20:$C$25) -> 5547.7223
B23: Marketing & Communications | C23: 0.1 | D23: =(D$13-$C$9)*C23/SUM($C$20:$C$25) -> 3503.2538 | E23: =(E$13-$C$9)*C23/SUM($C$20:$C$25) -> 6757.0499 | F23: =(F$13-$C$9)*C23/SUM($C$20:$C$25) -> 11095.445
B24: Logistics | C24: 0.051 | D24: =(D$13-$C$9)*C24/SUM($C$20:$C$25) -> 1786.6594 | E24: =(E$13-$C$9)*C24/SUM($C$20:$C$25) -> 3446.0954 | F24: =(F$13-$C$9)*C24/SUM($C$20:$C$25) -> 5658.6768
B25: Contingency | C25: 0.03 | D25: =(D$13-$C$9)*C25/SUM($C$20:$C$25) -> 1050.9761 | E25: =(E$13-$C$9)*C25/SUM($C$20:$C$25) -> 2027.115 | F25: =(F$13-$C$9)*C25/SUM($C$20:$C$25) -> 3328.6334
B26: Tổng chi phí | D26: =SUM(D19:D25) -> 35000 | E26: =SUM(E19:E25) -> 50000 | F26: =SUM(F19:F25) -> 70000
B27: — Tour Rights đã thanh toán (31/05/2025) | D27: =C7 -> 2600
B28: — Legends còn lại (prize + media + balance) | D28: =D19-C7 -> 16250
B30: KPI THEO KỊCH BẢN
B31: Lợi nhuận ròng (Net surplus) | D31: =D15-D26 -> 0 | E31: =E15-E26 -> 2500 | F31: =F15-F26 -> 7000
B32: Biên lợi nhuận (% doanh thu) | D32: =D31/D15 -> 0 | E32: =E31/E15 -> 0.047619048 | F32: =F31/F15 -> 0.090909091
B33: Cost coverage (DT / chi phí) | D33: =D15/D26 -> 1 | E33: =E15/E26 -> 1.05 | F33: =F15/F26 -> 1.1
B34: ROI (Net / chi phí) | D34: =D31/D26 -> 0 | E34: =E31/E26 -> 0.05 | F34: =F31/F26 -> 0.1
B36: PHÂN BỔ DOANH THU THEO NGUỒN
B37: Nguồn thu | C37: Allocation | D37: Conservative | E37: Base Case | F37: Aggressive
B38: Title Partner | C38: 0.35 | D38: =D$15*$C38 -> 12250 | E38: =E$15*$C38 -> 18375 | F38: =F$15*$C38 -> 26950
B39: Diamond Sponsor | C39: 0.25 | D39: =D$15*$C39 -> 8750 | E39: =E$15*$C39 -> 13125 | F39: =F$15*$C39 -> 19250
B40: Platinum Sponsor | C40: 0.15 | D40: =D$15*$C40 -> 5250 | E40: =E$15*$C40 -> 7875 | F40: =F$15*$C40 -> 11550
B41: Official Partner | C41: 0.1 | D41: =D$15*$C41 -> 3500 | E41: =E$15*$C41 -> 5250 | F41: =F$15*$C41 -> 7700
B42: VIP Packages | C42: 0.08 | D42: =D$15*$C42 -> 2800 | E42: =E$15*$C42 -> 4200 | F42: =F$15*$C42 -> 6160
B43: Pro-Am Slots | C43: 0.04 | D43: =D$15*$C43 -> 1400 | E43: =E$15*$C43 -> 2100 | F43: =F$15*$C43 -> 3080
B44: Booth & Activation | C44: 0.03 | D44: =D$15*$C44 -> 1050 | E44: =E$15*$C44 -> 1575 | F44: =F$15*$C44 -> 2310
B45: Tổng doanh thu | C45: =SUM(C38:C44) -> 1 | D45: =SUM(D38:D44) -> 35000 | E45: =SUM(E38:E44) -> 52500 | F45: =SUM(F38:F44) -> 77000
...

Sheet Funding & ROI
A1: FUNDING REQUIREMENT & ROI
A2: Đơn vị: triệu VND (trừ %). Kịch bản đang chọn. Doanh thu ≥ chi phí nên nhu cầu vốn chủ yếu là vốn lưu động (timing).
B4: NHU CẦU VỐN | F4: ROI & VALUE METRICS
B5: Tổng ngân sách (chi phí) | C5: {=INDEX(Scenario!$D$26:$F$26,1,Dashboard!$C$6)} -> 50000 | D5: =C5/1000 -> 50 | E5: ← tỷ VND | F5: Revenue / Cost (coverage) | H5: {=INDEX(Scenario!$D$33:$F$33,1,Dashboard!$C$6)} -> 1.05
B6: trong đó Tour Rights đã trả (sunk) | C6: =Scenario!C7 -> 2600 | D6: =C6/1000 -> 2.6 | F6: Net margin | H6: {=INDEX(Scenario!$D$32:$F$32,1,Dashboard!$C$6)} -> 0.047619048
B7: Tổng doanh thu (kịch bản chọn) | C7: {=INDEX(Scenario!$D$15:$F$15,1,Dashboard!$C$6)} -> 52500 | D7: =C7/1000 -> 52.5 | F7: ROI (Net / chi phí) | H7: {=INDEX(Scenario!$D$34:$F$34,1,Dashboard!$C$6)} -> 0.05
B8: Lợi nhuận ròng | C8: {=INDEX(Scenario!$D$31:$F$31,1,Dashboard!$C$6)} -> 2500 | D8: =C8/1000 -> 2.5 | F8: Est. media value (input) | H8: =18000 -> 18000
B9: Peak Working Capital (timing) | C9: =Cashflow!$C$3 -> 2937.8525 | D9: =C9/1000 -> 2.9378525 | F9: Tổng giá trị (revenue + media) | H9: {=INDEX(Scenario!$D$15:$F$15,1,Dashboard!$C$6)+H8} -> 70500
B10: Đệm an toàn (10% WC) | C10: =C9*0.1 -> 293.78525 | D10: =C10/1000 -> 0.29378525 | F10: Total value / Cost | H10: {=H9/INDEX(Scenario!$D$26:$F$26,1,Dashboard!$C$6)} -> 1.41
B11: FACILITY VỐN LƯU ĐỘNG ĐỀ XUẤT | C11: =C9+C10 -> 3231.6377 | D11: =C11/1000 -> 3.2316377 | F11: Year-2 (2027) renewal upside | H11: {=INDEX(Scenario!$D$15:$F$15,1,Dashboard!$C$6)*0.2} -> 10500
B13: NGUỒN VỐN ĐỀ XUẤT (illustrative) | F13: Giá trị vô hình (định tính):
B14: Nguồn | C14: Số tiền (triệu) | D14: % facility | F14: Nation branding · xúc tiến đầu tư · du lịch cao cấp · hệ sinh thái golf · IP thường niên 2027+.
B15: Đối tác chiến lược / Host | C15: =$C$5*0.4 -> 20000 | D15: =C15/$C$5 -> 0.4
B16: Hỗ trợ ngân sách & xúc tiến | C16: =$C$5*0.15 -> 7500 | D16: =C16/$C$5 -> 0.15
B17: Hạn mức vốn lưu động (bank) | C17: =$C$5*0.3 -> 15000 | D17: =C17/$C$5 -> 0.3
B18: Nhà đầu tư / equity | C18: =$C$5*0.15 -> 7500 | D18: =C18/$C$5 -> 0.15
B19: TỔNG NGUỒN | C19: =SUM(C15:C18) -> 50000 | D19: =SUM(D15:D18) -> 1

Sheet Risk
A1: RISK & SENSITIVITY ANALYSIS
A2: Net result (triệu) = DT mục tiêu (kịch bản chọn) × %đạt − Chi phí × (1+%vượt).
B4: SENSITIVITY: Net result (triệu) — hàng = % doanh thu đạt, cột = % chi phí vượt
B5: Rev% \ Cost% | C5: 0 | D5: 0.05 | E5: 0.1 | F5: 0.15 | G5: 0.2
B6: 0.8 | C6: {=INDEX(Scenario!$D$15:$F$15,1,Dashboard!$C$6)*0.8-INDEX(Scenario!$D$26:$F$26,1,Dashboard!$C$6)*(1+0)} -> -8000 | D6: {=INDEX(Scenario!$D$15:$F$15,1,Dashboard!$C$6)*0.8-INDEX(Scenario!$D$26:$F$26,1,Dashboard!$C$6)*(1+0.05)} -> -10500 | E6: {=INDEX(Scenario!$D$15:$F$15,1,Dashboard!$C$6)*0.8-INDEX(Scenario!$D$26:$F$26,1,Dashboard!$C$6)*(1+0.1)} -> -13000 | F6: {=INDEX(Scenario!$D$15:$F$15,1,Dashboard!$C$6)*0.8-INDEX(Scenario!$D$26:$F$26,1,Dashboard!$C$6)*(1+0.15)} -> -15500 | G6: {=INDEX(Scenario!$D$15:$F$15,1,Dashboard!$C$6)*0.8-INDEX(Scenario!$D$26:$F$26,1,Dashboard!$C$6)*(1+0.2)} -> -18000
B7: 0.9 | C7: {=INDEX(Scenario!$D$15:$F$15,1,Dashboard!$C$6)*0.9-INDEX(Scenario!$D$26:$F$26,1,Dashboard!$C$6)*(1+0)} -> -2750 | D7: {=INDEX(Scenario!$D$15:$F$15,1,Dashboard!$C$6)*0.9-INDEX(Scenario!$D$26:$F$26,1,Dashboard!$C$6)*(1+0.05)} -> -5250 | E7: {=INDEX(Scenario!$D$15:$F$15,1,Dashboard!$C$6)*0.9-INDEX(Scenario!$D$26:$F$26,1,Dashboard!$C$6)*(1+0.1)} -> -7750 | F7: {=INDEX(Scenario!$D$15:$F$15,1,Dashboard!$C$6)*0.9-INDEX(Scenario!$D$26:$F$26,1,Dashboard!$C$6)*(1+0.15)} -> -10250 | G7: {=INDEX(Scenario!$D$15:$F$15,1,Dashboard!$C$6)*0.9-INDEX(Scenario!$D$26:$F$26,1,Dashboard!$C$6)*(1+0.2)} -> -12750
B8: 1 | C8: {=INDEX(Scenario!$D$15:$F$15,1,Dashboard!$C$6)*1-INDEX(Scenario!$D$26:$F$26,1,Dashboard!$C$6)*(1+0)} -> 2500 | D8: {=INDEX(Scenario!$D$15:$F$15,1,Dashboard!$C$6)*1-INDEX(Scenario!$D$26:$F$26,1,Dashboard!$C$6)*(1+0.05)} -> 0 | E8: {=INDEX(Scenario!$D$15:$F$15,1,Dashboard!$C$6)*1-INDEX(Scenario!$D$26:$F$26,1,Dashboard!$C$6)*(1+0.1)} -> -2500 | F8: {=INDEX(Scenario!$D$15:$F$15,1,Dashboard!$C$6)*1-INDEX(Scenario!$D$26:$F$26,1,Dashboard!$C$6)*(1+0.15)} -> -5000 | G8: {=INDEX(Scenario!$D$15:$F$15,1,Dashboard!$C$6)*1-INDEX(Scenario!$D$26:$F$26,1,Dashboard!$C$6)*(1+0.2)} -> -7500
B9: 1.05 | C9: {=INDEX(Scenario!$D$15:$F$15,1,Dashboard!$C$6)*1.05-INDEX(Scenario!$D$26:$F$26,1,Dashboard!$C$6)*(1+0)} -> 5125 | D9: {=INDEX(Scenario!$D$15:$F$15,1,Dashboard!$C$6)*1.05-INDEX(Scenario!$D$26:$F$26,1,Dashboard!$C$6)*(1+0.05)} -> 2625 | E9: {=INDEX(Scenario!$D$15:$F$15,1,Dashboard!$C$6)*1.05-INDEX(Scenario!$D$26:$F$26,1,Dashboard!$C$6)*(1+0.1)} -> 125 | F9: {=INDEX(Scenario!$D$15:$F$15,1,Dashboard!$C$6)*1.05-INDEX(Scenario!$D$26:$F$26,1,Dashboard!$C$6)*(1+0.15)} -> -2375 | G9: {=INDEX(Scenario!$D$15:$F$15,1,Dashboard!$C$6)*1.05-INDEX(Scenario!$D$26:$F$26,1,Dashboard!$C$6)*(1+0.2)} -> -4875
B10: 1.1 | C10: {=INDEX(Scenario!$D$15:$F$15,1,Dashboard!$C$6)*1.1-INDEX(Scenario!$D$26:$F$26,1,Dashboard!$C$6)*(1+0)} -> 7750 | D10: {=INDEX(Scenario!$D$15:$F$15,1,Dashboard!$C$6)*1.1-INDEX(Scenario!$D$26:$F$26,1,Dashboard!$C$6)*(1+0.05)} -> 5250 | E10: {=INDEX(Scenario!$D$15:$F$15,1,Dashboard!$C$6)*1.1-INDEX(Scenario!$D$26:$F$26,1,Dashboard!$C$6)*(1+0.1)} -> 2750 | F10: {=INDEX(Scenario!$D$15:$F$15,1,Dashboard!$C$6)*1.1-INDEX(Scenario!$D$26:$F$26,1,Dashboard!$C$6)*(1+0.15)} -> 250 | G10: {=INDEX(Scenario!$D$15:$F$15,1,Dashboard!$C$6)*1.1-INDEX(Scenario!$D$26:$F$26,1,Dashboard!$C$6)*(1+0.2)} -> -2250
B11: 1.2 | C11: {=INDEX(Scenario!$D$15:$F$15,1,Dashboard!$C$6)*1.2-INDEX(Scenario!$D$26:$F$26,1,Dashboard!$C$6)*(1+0)} -> 13000 | D11: {=INDEX(Scenario!$D$15:$F$15,1,Dashboard!$C$6)*1.2-INDEX(Scenario!$D$26:$F$26,1,Dashboard!$C$6)*(1+0.05)} -> 10500 | E11: {=INDEX(Scenario!$D$15:$F$15,1,Dashboard!$C$6)*1.2-INDEX(Scenario!$D$26:$F$26,1,Dashboard!$C$6)*(1+0.1)} -> 8000 | F11: {=INDEX(Scenario!$D$15:$F$15,1,Dashboard!$C$6)*1.2-INDEX(Scenario!$D$26:$F$26,1,Dashboard!$C$6)*(1+0.15)} -> 5500 | G11: {=INDEX(Scenario!$D$15:$F$15,1,Dashboard!$C$6)*1.2-INDEX(Scenario!$D$26:$F$26,1,Dashboard!$C$6)*(1+0.2)} -> 3000
B13: Breakeven analysis
B14: % doanh thu cần đạt để hoà vốn | C14: {=INDEX(Scenario!$D$26:$F$26,1,Dashboard!$C$6)/INDEX(Scenario!$D$15:$F$15,1,Dashboard!$C$6)} -> 0.95238095 | D14: → Conservative (coverage 100%): cần 100%. Base/Aggressive có biên an toàn.
B16: KEY RISK DRIVERS & MITIGATION
B17: Rủi ro | C17: Khả năng | D17: Tác động | E17: Giảm thiểu
B18: Giải thưởng (prize) lớn — đối tác chia sẻ | C18: T.Bình | D18: Cao | E18: HĐ chia sẻ prize, milestone trước sự kiện, FX buffer
B19: Sponsorship dưới mục tiêu | C19: T.Bình | D19: Cao | E19: Pipeline ≥3×, anchor Title sớm, gói linh hoạt
B20: Chi phí vận hành vượt | C20: T.Bình | D20: T.Bình | E20: Contingency, hợp đồng giá cố định, change-request control
B21: Dòng tiền lệch pha | C21: Cao | D21: Cao | E21: Facility vốn lưu động, deposit sponsor sớm, milestone vendor
B22: Permit/chính quyền chậm | C22: T.Thấp | D22: Cao | E22: Permit roadmap T-30, government lead
B23: Tỷ giá USD/VND (Legends fee) | C23: T.Bình | D23: Cao | E23: Rights đã trả; FX buffer cho prize/media còn lại
